Watching for file changes with StatReloader
[11/Nov/2020 03:06:24] "GET /api/products/ HTTP/1.1" 200 18589
[11/Nov/2020 03:06:24] "GET /static/rest_framework/css/bootstrap.min.css HTTP/1.1" 304 0
[11/Nov/2020 03:06:24] "GET /static/rest_framework/css/bootstrap-tweaks.css HTTP/1.1" 304 0
[11/Nov/2020 03:06:24] "GET /static/rest_framework/css/prettify.css HTTP/1.1" 304 0
[11/Nov/2020 03:06:24] "GET /static/rest_framework/js/jquery-3.5.1.min.js HTTP/1.1" 304 0
[11/Nov/2020 03:06:24] "GET /static/rest_framework/css/default.css HTTP/1.1" 304 0
[11/Nov/2020 03:06:24] "GET /static/rest_framework/js/ajax-form.js HTTP/1.1" 304 0
[11/Nov/2020 03:06:24] "GET /static/rest_framework/js/bootstrap.min.js HTTP/1.1" 304 0
[11/Nov/2020 03:06:24] "GET /static/rest_framework/js/csrf.js HTTP/1.1" 304 0
[11/Nov/2020 03:06:24] "GET /static/rest_framework/js/prettify-min.js HTTP/1.1" 304 0
[11/Nov/2020 03:06:24] "GET /static/rest_framework/js/default.js HTTP/1.1" 304 0
[11/Nov/2020 03:06:24] "GET /static/rest_framework/img/grid.png HTTP/1.1" 304 0
Not Found: /favicon.ico
[11/Nov/2020 03:06:24] "GET /favicon.ico HTTP/1.1" 404 2314
[11/Nov/2020 03:06:49] "GET /docs/ HTTP/1.1" 200 140729
[11/Nov/2020 03:06:49] "GET /static/rest_framework/css/bootstrap-theme.min.css HTTP/1.1" 304 0
[11/Nov/2020 03:06:49] "GET /static/rest_framework/css/font-awesome-4.0.3.css HTTP/1.1" 304 0
[11/Nov/2020 03:06:49] "GET /static/rest_framework/js/coreapi-0.1.1.js HTTP/1.1" 304 0
[11/Nov/2020 03:06:49] "GET /static/rest_framework/docs/css/base.css HTTP/1.1" 304 0
[11/Nov/2020 03:06:49] "GET /static/rest_framework/docs/css/jquery.json-view.min.css HTTP/1.1" 304 0
[11/Nov/2020 03:06:49] "GET /docs/schema.js HTTP/1.1" 200 10740
[11/Nov/2020 03:06:49] "GET /static/rest_framework/fonts/fontawesome-webfont.woff?v=4.0.3 HTTP/1.1" 304 0
[11/Nov/2020 03:06:49] "GET /static/rest_framework/docs/js/api.js HTTP/1.1" 304 0
[11/Nov/2020 03:06:49] "GET /static/rest_framework/docs/js/jquery.json-view.min.js HTTP/1.1" 304 0
[11/Nov/2020 03:14:44] "GET /api/customers/ HTTP/1.1" 200 10397
[11/Nov/2020 07:26:04] "GET /api/products/ HTTP/1.1" 200 1042
[11/Nov/2020 07:26:04] "GET /media/products/nike%20shoes%203/MSRA_Facility_Contact.png HTTP/1.1" 304 0
[11/Nov/2020 07:26:04] "GET /media/products/nike%20shoes%202/MSRA_Facility_Contact.png HTTP/1.1" 304 0
[11/Nov/2020 07:26:04] "GET /media/products/nike%20shoes%201/MSRA_Intern_Support_Contact.png HTTP/1.1" 304 0
[11/Nov/2020 07:26:31] "GET /api/products/2/ HTTP/1.1" 200 344
[11/Nov/2020 07:30:10] "GET /api/products/ HTTP/1.1" 200 1042
[11/Nov/2020 07:32:16] "GET /api/products/ HTTP/1.1" 200 1042
[11/Nov/2020 07:32:18] "GET /api/products/ HTTP/1.1" 200 1042
[11/Nov/2020 07:32:35] "GET /api/products/ HTTP/1.1" 200 1042
[11/Nov/2020 07:32:56] "GET /api/products/ HTTP/1.1" 200 1042
[11/Nov/2020 08:08:59] "GET /api/products/ HTTP/1.1" 200 1042
[11/Nov/2020 08:15:46] "GET /api/products/ HTTP/1.1" 200 1042
/mnt/c/Users/v-bowenz/OneDrive - Microsoft/Code/team-ai-virtual-try-on/code/backend/BackendManagement/models.py changed, reloading.
Performing system checks...

System check identified no issues (0 silenced).
November 11, 2020 - 03:06:07
Django version 3.1.2, using settings 'backend.settings'
Starting development server at http://0.0.0.0:8000/
Quit the server with CONTROL-C.
Watching for file changes with StatReloader
Not Found: /
[11/Nov/2020 08:34:47] "GET / HTTP/1.1" 404 2263
Not Found: /
[11/Nov/2020 08:34:47] "GET / HTTP/1.1" 404 2263
Not Found: /
[11/Nov/2020 08:34:47] "GET / HTTP/1.1" 404 2263
Not Found: /favicon.ico
[11/Nov/2020 08:34:48] "GET /favicon.ico HTTP/1.1" 404 2314
[11/Nov/2020 08:35:18] "GET /api/products HTTP/1.1" 301 0
[11/Nov/2020 08:35:18] "GET /api/products/ HTTP/1.1" 200 18589
[11/Nov/2020 08:35:18] "GET /static/rest_framework/css/bootstrap.min.css HTTP/1.1" 304 0
[11/Nov/2020 08:35:18] "GET /static/rest_framework/css/bootstrap-tweaks.css HTTP/1.1" 304 0
[11/Nov/2020 08:35:18] "GET /static/rest_framework/css/prettify.css HTTP/1.1" 304 0
[11/Nov/2020 08:35:18] "GET /static/rest_framework/js/ajax-form.js HTTP/1.1" 304 0
[11/Nov/2020 08:35:18] "GET /static/rest_framework/css/default.css HTTP/1.1" 304 0
[11/Nov/2020 08:35:18] "GET /static/rest_framework/js/bootstrap.min.js HTTP/1.1" 304 0
[11/Nov/2020 08:35:18] "GET /static/rest_framework/js/jquery-3.5.1.min.js HTTP/1.1" 304 0
[11/Nov/2020 08:35:18] "GET /static/rest_framework/js/prettify-min.js HTTP/1.1" 304 0
[11/Nov/2020 08:35:18] "GET /static/rest_framework/js/default.js HTTP/1.1" 304 0
[11/Nov/2020 08:35:18] "GET /static/rest_framework/js/csrf.js HTTP/1.1" 304 0
[11/Nov/2020 08:35:18] "GET /static/rest_framework/img/grid.png HTTP/1.1" 304 0
[11/Nov/2020 08:35:21] "OPTIONS /api/products/ HTTP/1.1" 200 19719
[11/Nov/2020 08:35:29] "OPTIONS /api/products/ HTTP/1.1" 200 19719
Bad Request: /api/products/
[11/Nov/2020 08:35:52] "POST /api/products/ HTTP/1.1" 400 112
[11/Nov/2020 08:35:56] "GET /api/products/ HTTP/1.1" 200 1042
[11/Nov/2020 08:36:05] "DELETE /api/products/1 HTTP/1.1" 301 0
[11/Nov/2020 08:36:05] "GET /api/products/1/ HTTP/1.1" 200 350
[11/Nov/2020 08:36:11] "DELETE /api/products/2 HTTP/1.1" 301 0
[11/Nov/2020 08:36:11] "GET /api/products/2/ HTTP/1.1" 200 344
[11/Nov/2020 08:36:14] "DELETE /api/products/3 HTTP/1.1" 301 0
[11/Nov/2020 08:36:14] "GET /api/products/3/ HTTP/1.1" 200 344
[11/Nov/2020 08:36:19] "GET /api/products/ HTTP/1.1" 200 1042
[11/Nov/2020 08:37:27] "OPTIONS /api/products/ HTTP/1.1" 200 19719
[11/Nov/2020 08:37:28] "OPTIONS /api/products/ HTTP/1.1" 200 19719
[11/Nov/2020 08:37:28] "OPTIONS /api/products/ HTTP/1.1" 200 19719
[11/Nov/2020 08:37:29] "GET /api/products/ HTTP/1.1" 200 18589
/mnt/c/Users/v-bowenz/OneDrive - Microsoft/Code/team-ai-virtual-try-on/code/backend/BackendManagement/views.py changed, reloading.
Performing system checks...

System check identified no issues (0 silenced).
November 11, 2020 - 08:33:58
Django version 3.1.2, using settings 'backend.settings'
Starting development server at http://0.0.0.0:8000/
Quit the server with CONTROL-C.
Watching for file changes with StatReloader
Exception in thread django-main-thread:
Traceback (most recent call last):
  File "/usr/lib/python3.6/threading.py", line 916, in _bootstrap_inner
    self.run()
  File "/usr/lib/python3.6/threading.py", line 864, in run
    self._target(*self._args, **self._kwargs)
  File "/home/bw/.local/lib/python3.6/site-packages/django/utils/autoreload.py", line 53, in wrapper
    fn(*args, **kwargs)
  File "/home/bw/.local/lib/python3.6/site-packages/django/core/management/commands/runserver.py", line 118, in inner_run
    self.check(display_num_errors=True)
  File "/home/bw/.local/lib/python3.6/site-packages/django/core/management/base.py", line 396, in check
    databases=databases,
  File "/home/bw/.local/lib/python3.6/site-packages/django/core/checks/registry.py", line 70, in run_checks
    new_errors = check(app_configs=app_configs, databases=databases)
  File "/home/bw/.local/lib/python3.6/site-packages/django/core/checks/urls.py", line 13, in check_url_config
    return check_resolver(resolver)
  File "/home/bw/.local/lib/python3.6/site-packages/django/core/checks/urls.py", line 23, in check_resolver
    return check_method()
  File "/home/bw/.local/lib/python3.6/site-packages/django/urls/resolvers.py", line 408, in check
    for pattern in self.url_patterns:
  File "/home/bw/.local/lib/python3.6/site-packages/django/utils/functional.py", line 48, in __get__
    res = instance.__dict__[self.name] = self.func(instance)
  File "/home/bw/.local/lib/python3.6/site-packages/django/urls/resolvers.py", line 589, in url_patterns
    patterns = getattr(self.urlconf_module, "urlpatterns", self.urlconf_module)
  File "/home/bw/.local/lib/python3.6/site-packages/django/utils/functional.py", line 48, in __get__
    res = instance.__dict__[self.name] = self.func(instance)
  File "/home/bw/.local/lib/python3.6/site-packages/django/urls/resolvers.py", line 582, in urlconf_module
    return import_module(self.urlconf_name)
  File "/usr/lib/python3.6/importlib/__init__.py", line 126, in import_module
    return _bootstrap._gcd_import(name[level:], package, level)
  File "<frozen importlib._bootstrap>", line 994, in _gcd_import
  File "<frozen importlib._bootstrap>", line 971, in _find_and_load
  File "<frozen importlib._bootstrap>", line 955, in _find_and_load_unlocked
  File "<frozen importlib._bootstrap>", line 665, in _load_unlocked
  File "<frozen importlib._bootstrap_external>", line 678, in exec_module
  File "<frozen importlib._bootstrap>", line 219, in _call_with_frames_removed
  File "/mnt/c/Users/v-bowenz/OneDrive - Microsoft/Code/team-ai-virtual-try-on/code/backend/backend/urls.py", line 25, in <module>
    path('api/', include('BackendManagement.urls')),
  File "/home/bw/.local/lib/python3.6/site-packages/django/urls/conf.py", line 34, in include
    urlconf_module = import_module(urlconf_module)
  File "/usr/lib/python3.6/importlib/__init__.py", line 126, in import_module
    return _bootstrap._gcd_import(name[level:], package, level)
  File "<frozen importlib._bootstrap>", line 994, in _gcd_import
  File "<frozen importlib._bootstrap>", line 971, in _find_and_load
  File "<frozen importlib._bootstrap>", line 955, in _find_and_load_unlocked
  File "<frozen importlib._bootstrap>", line 665, in _load_unlocked
  File "<frozen importlib._bootstrap_external>", line 678, in exec_module
  File "<frozen importlib._bootstrap>", line 219, in _call_with_frames_removed
  File "/mnt/c/Users/v-bowenz/OneDrive - Microsoft/Code/team-ai-virtual-try-on/code/backend/BackendManagement/urls.py", line 6, in <module>
    from BackendManagement.views import *
  File "/mnt/c/Users/v-bowenz/OneDrive - Microsoft/Code/team-ai-virtual-try-on/code/backend/BackendManagement/views.py", line 114
    def
       ^
SyntaxError: invalid syntax

/mnt/c/Users/v-bowenz/OneDrive - Microsoft/Code/team-ai-virtual-try-on/code/backend/BackendManagement/views.py changed, reloading.
Performing system checks...

Watching for file changes with StatReloader
Exception in thread django-main-thread:
Traceback (most recent call last):
  File "/usr/lib/python3.6/threading.py", line 916, in _bootstrap_inner
    self.run()
  File "/usr/lib/python3.6/threading.py", line 864, in run
    self._target(*self._args, **self._kwargs)
  File "/home/bw/.local/lib/python3.6/site-packages/django/utils/autoreload.py", line 53, in wrapper
    fn(*args, **kwargs)
  File "/home/bw/.local/lib/python3.6/site-packages/django/core/management/commands/runserver.py", line 118, in inner_run
    self.check(display_num_errors=True)
  File "/home/bw/.local/lib/python3.6/site-packages/django/core/management/base.py", line 396, in check
    databases=databases,
  File "/home/bw/.local/lib/python3.6/site-packages/django/core/checks/registry.py", line 70, in run_checks
    new_errors = check(app_configs=app_configs, databases=databases)
  File "/home/bw/.local/lib/python3.6/site-packages/django/core/checks/urls.py", line 13, in check_url_config
    return check_resolver(resolver)
  File "/home/bw/.local/lib/python3.6/site-packages/django/core/checks/urls.py", line 23, in check_resolver
    return check_method()
  File "/home/bw/.local/lib/python3.6/site-packages/django/urls/resolvers.py", line 408, in check
    for pattern in self.url_patterns:
  File "/home/bw/.local/lib/python3.6/site-packages/django/utils/functional.py", line 48, in __get__
    res = instance.__dict__[self.name] = self.func(instance)
  File "/home/bw/.local/lib/python3.6/site-packages/django/urls/resolvers.py", line 589, in url_patterns
    patterns = getattr(self.urlconf_module, "urlpatterns", self.urlconf_module)
  File "/home/bw/.local/lib/python3.6/site-packages/django/utils/functional.py", line 48, in __get__
    res = instance.__dict__[self.name] = self.func(instance)
  File "/home/bw/.local/lib/python3.6/site-packages/django/urls/resolvers.py", line 582, in urlconf_module
    return import_module(self.urlconf_name)
  File "/usr/lib/python3.6/importlib/__init__.py", line 126, in import_module
    return _bootstrap._gcd_import(name[level:], package, level)
  File "<frozen importlib._bootstrap>", line 994, in _gcd_import
  File "<frozen importlib._bootstrap>", line 971, in _find_and_load
  File "<frozen importlib._bootstrap>", line 955, in _find_and_load_unlocked
  File "<frozen importlib._bootstrap>", line 665, in _load_unlocked
  File "<frozen importlib._bootstrap_external>", line 678, in exec_module
  File "<frozen importlib._bootstrap>", line 219, in _call_with_frames_removed
  File "/mnt/c/Users/v-bowenz/OneDrive - Microsoft/Code/team-ai-virtual-try-on/code/backend/backend/urls.py", line 25, in <module>
    path('api/', include('BackendManagement.urls')),
  File "/home/bw/.local/lib/python3.6/site-packages/django/urls/conf.py", line 34, in include
    urlconf_module = import_module(urlconf_module)
  File "/usr/lib/python3.6/importlib/__init__.py", line 126, in import_module
    return _bootstrap._gcd_import(name[level:], package, level)
  File "<frozen importlib._bootstrap>", line 994, in _gcd_import
  File "<frozen importlib._bootstrap>", line 971, in _find_and_load
  File "<frozen importlib._bootstrap>", line 955, in _find_and_load_unlocked
  File "<frozen importlib._bootstrap>", line 665, in _load_unlocked
  File "<frozen importlib._bootstrap_external>", line 678, in exec_module
  File "<frozen importlib._bootstrap>", line 219, in _call_with_frames_removed
  File "/mnt/c/Users/v-bowenz/OneDrive - Microsoft/Code/team-ai-virtual-try-on/code/backend/BackendManagement/urls.py", line 6, in <module>
    from BackendManagement.views import *
  File "/mnt/c/Users/v-bowenz/OneDrive - Microsoft/Code/team-ai-virtual-try-on/code/backend/BackendManagement/views.py", line 114
    def destroy()
                ^
SyntaxError: invalid syntax

/mnt/c/Users/v-bowenz/OneDrive - Microsoft/Code/team-ai-virtual-try-on/code/backend/BackendManagement/views.py changed, reloading.
Performing system checks...

Watching for file changes with StatReloader
Exception in thread django-main-thread:
Traceback (most recent call last):
  File "/usr/lib/python3.6/threading.py", line 916, in _bootstrap_inner
    self.run()
  File "/usr/lib/python3.6/threading.py", line 864, in run
    self._target(*self._args, **self._kwargs)
  File "/home/bw/.local/lib/python3.6/site-packages/django/utils/autoreload.py", line 53, in wrapper
    fn(*args, **kwargs)
  File "/home/bw/.local/lib/python3.6/site-packages/django/core/management/commands/runserver.py", line 118, in inner_run
    self.check(display_num_errors=True)
  File "/home/bw/.local/lib/python3.6/site-packages/django/core/management/base.py", line 396, in check
    databases=databases,
  File "/home/bw/.local/lib/python3.6/site-packages/django/core/checks/registry.py", line 70, in run_checks
    new_errors = check(app_configs=app_configs, databases=databases)
  File "/home/bw/.local/lib/python3.6/site-packages/django/core/checks/urls.py", line 13, in check_url_config
    return check_resolver(resolver)
  File "/home/bw/.local/lib/python3.6/site-packages/django/core/checks/urls.py", line 23, in check_resolver
    return check_method()
  File "/home/bw/.local/lib/python3.6/site-packages/django/urls/resolvers.py", line 408, in check
    for pattern in self.url_patterns:
  File "/home/bw/.local/lib/python3.6/site-packages/django/utils/functional.py", line 48, in __get__
    res = instance.__dict__[self.name] = self.func(instance)
  File "/home/bw/.local/lib/python3.6/site-packages/django/urls/resolvers.py", line 589, in url_patterns
    patterns = getattr(self.urlconf_module, "urlpatterns", self.urlconf_module)
  File "/home/bw/.local/lib/python3.6/site-packages/django/utils/functional.py", line 48, in __get__
    res = instance.__dict__[self.name] = self.func(instance)
  File "/home/bw/.local/lib/python3.6/site-packages/django/urls/resolvers.py", line 582, in urlconf_module
    return import_module(self.urlconf_name)
  File "/usr/lib/python3.6/importlib/__init__.py", line 126, in import_module
    return _bootstrap._gcd_import(name[level:], package, level)
  File "<frozen importlib._bootstrap>", line 994, in _gcd_import
  File "<frozen importlib._bootstrap>", line 971, in _find_and_load
  File "<frozen importlib._bootstrap>", line 955, in _find_and_load_unlocked
  File "<frozen importlib._bootstrap>", line 665, in _load_unlocked
  File "<frozen importlib._bootstrap_external>", line 678, in exec_module
  File "<frozen importlib._bootstrap>", line 219, in _call_with_frames_removed
  File "/mnt/c/Users/v-bowenz/OneDrive - Microsoft/Code/team-ai-virtual-try-on/code/backend/backend/urls.py", line 25, in <module>
    path('api/', include('BackendManagement.urls')),
  File "/home/bw/.local/lib/python3.6/site-packages/django/urls/conf.py", line 34, in include
    urlconf_module = import_module(urlconf_module)
  File "/usr/lib/python3.6/importlib/__init__.py", line 126, in import_module
    return _bootstrap._gcd_import(name[level:], package, level)
  File "<frozen importlib._bootstrap>", line 994, in _gcd_import
  File "<frozen importlib._bootstrap>", line 971, in _find_and_load
  File "<frozen importlib._bootstrap>", line 955, in _find_and_load_unlocked
  File "<frozen importlib._bootstrap>", line 665, in _load_unlocked
  File "<frozen importlib._bootstrap_external>", line 678, in exec_module
  File "<frozen importlib._bootstrap>", line 219, in _call_with_frames_removed
  File "/mnt/c/Users/v-bowenz/OneDrive - Microsoft/Code/team-ai-virtual-try-on/code/backend/BackendManagement/urls.py", line 6, in <module>
    from BackendManagement.views import *
  File "/mnt/c/Users/v-bowenz/OneDrive - Microsoft/Code/team-ai-virtual-try-on/code/backend/BackendManagement/views.py", line 115
    
    ^
SyntaxError: unexpected EOF while parsing

/mnt/c/Users/v-bowenz/OneDrive - Microsoft/Code/team-ai-virtual-try-on/code/backend/BackendManagement/views.py changed, reloading.
Performing system checks...

Watching for file changes with StatReloader
/mnt/c/Users/v-bowenz/OneDrive - Microsoft/Code/team-ai-virtual-try-on/code/backend/BackendManagement/views.py changed, reloading.
Performing system checks...

System check identified no issues (0 silenced).
November 11, 2020 - 08:39:50
Django version 3.1.2, using settings 'backend.settings'
Starting development server at http://0.0.0.0:8000/
Quit the server with CONTROL-C.
Watching for file changes with StatReloader
/mnt/c/Users/v-bowenz/OneDrive - Microsoft/Code/team-ai-virtual-try-on/code/backend/BackendManagement/views.py changed, reloading.
Performing system checks...

System check identified no issues (0 silenced).
November 11, 2020 - 08:39:52
Django version 3.1.2, using settings 'backend.settings'
Starting development server at http://0.0.0.0:8000/
Quit the server with CONTROL-C.
Watching for file changes with StatReloader
/mnt/c/Users/v-bowenz/OneDrive - Microsoft/Code/team-ai-virtual-try-on/code/backend/BackendManagement/views.py changed, reloading.
Performing system checks...

System check identified no issues (0 silenced).
November 11, 2020 - 08:39:56
Django version 3.1.2, using settings 'backend.settings'
Starting development server at http://0.0.0.0:8000/
Quit the server with CONTROL-C.
Watching for file changes with StatReloader
/mnt/c/Users/v-bowenz/OneDrive - Microsoft/Code/team-ai-virtual-try-on/code/backend/BackendManagement/views.py changed, reloading.
Performing system checks...

System check identified no issues (0 silenced).
November 11, 2020 - 08:39:59
Django version 3.1.2, using settings 'backend.settings'
Starting development server at http://0.0.0.0:8000/
Quit the server with CONTROL-C.
Watching for file changes with StatReloader
/mnt/c/Users/v-bowenz/OneDrive - Microsoft/Code/team-ai-virtual-try-on/code/backend/BackendManagement/views.py changed, reloading.
Performing system checks...

System check identified no issues (0 silenced).
November 11, 2020 - 08:40:02
Django version 3.1.2, using settings 'backend.settings'
Starting development server at http://0.0.0.0:8000/
Quit the server with CONTROL-C.
Watching for file changes with StatReloader
Exception in thread django-main-thread:
Traceback (most recent call last):
  File "/usr/lib/python3.6/threading.py", line 916, in _bootstrap_inner
    self.run()
  File "/usr/lib/python3.6/threading.py", line 864, in run
    self._target(*self._args, **self._kwargs)
  File "/home/bw/.local/lib/python3.6/site-packages/django/utils/autoreload.py", line 53, in wrapper
    fn(*args, **kwargs)
  File "/home/bw/.local/lib/python3.6/site-packages/django/core/management/commands/runserver.py", line 118, in inner_run
    self.check(display_num_errors=True)
  File "/home/bw/.local/lib/python3.6/site-packages/django/core/management/base.py", line 396, in check
    databases=databases,
  File "/home/bw/.local/lib/python3.6/site-packages/django/core/checks/registry.py", line 70, in run_checks
    new_errors = check(app_configs=app_configs, databases=databases)
  File "/home/bw/.local/lib/python3.6/site-packages/django/core/checks/urls.py", line 13, in check_url_config
    return check_resolver(resolver)
  File "/home/bw/.local/lib/python3.6/site-packages/django/core/checks/urls.py", line 23, in check_resolver
    return check_method()
  File "/home/bw/.local/lib/python3.6/site-packages/django/urls/resolvers.py", line 408, in check
    for pattern in self.url_patterns:
  File "/home/bw/.local/lib/python3.6/site-packages/django/utils/functional.py", line 48, in __get__
    res = instance.__dict__[self.name] = self.func(instance)
  File "/home/bw/.local/lib/python3.6/site-packages/django/urls/resolvers.py", line 589, in url_patterns
    patterns = getattr(self.urlconf_module, "urlpatterns", self.urlconf_module)
  File "/home/bw/.local/lib/python3.6/site-packages/django/utils/functional.py", line 48, in __get__
    res = instance.__dict__[self.name] = self.func(instance)
  File "/home/bw/.local/lib/python3.6/site-packages/django/urls/resolvers.py", line 582, in urlconf_module
    return import_module(self.urlconf_name)
  File "/usr/lib/python3.6/importlib/__init__.py", line 126, in import_module
    return _bootstrap._gcd_import(name[level:], package, level)
  File "<frozen importlib._bootstrap>", line 994, in _gcd_import
  File "<frozen importlib._bootstrap>", line 971, in _find_and_load
  File "<frozen importlib._bootstrap>", line 955, in _find_and_load_unlocked
  File "<frozen importlib._bootstrap>", line 665, in _load_unlocked
  File "<frozen importlib._bootstrap_external>", line 678, in exec_module
  File "<frozen importlib._bootstrap>", line 219, in _call_with_frames_removed
  File "/mnt/c/Users/v-bowenz/OneDrive - Microsoft/Code/team-ai-virtual-try-on/code/backend/backend/urls.py", line 25, in <module>
    path('api/', include('BackendManagement.urls')),
  File "/home/bw/.local/lib/python3.6/site-packages/django/urls/conf.py", line 34, in include
    urlconf_module = import_module(urlconf_module)
  File "/usr/lib/python3.6/importlib/__init__.py", line 126, in import_module
    return _bootstrap._gcd_import(name[level:], package, level)
  File "<frozen importlib._bootstrap>", line 994, in _gcd_import
  File "<frozen importlib._bootstrap>", line 971, in _find_and_load
  File "<frozen importlib._bootstrap>", line 955, in _find_and_load_unlocked
  File "<frozen importlib._bootstrap>", line 665, in _load_unlocked
  File "<frozen importlib._bootstrap_external>", line 678, in exec_module
  File "<frozen importlib._bootstrap>", line 219, in _call_with_frames_removed
  File "/mnt/c/Users/v-bowenz/OneDrive - Microsoft/Code/team-ai-virtual-try-on/code/backend/BackendManagement/urls.py", line 6, in <module>
    from BackendManagement.views import *
  File "<frozen importlib._bootstrap>", line 971, in _find_and_load
  File "<frozen importlib._bootstrap>", line 955, in _find_and_load_unlocked
  File "<frozen importlib._bootstrap>", line 665, in _load_unlocked
  File "<frozen importlib._bootstrap_external>", line 674, in exec_module
  File "<frozen importlib._bootstrap_external>", line 780, in get_code
  File "<frozen importlib._bootstrap_external>", line 833, in get_data
OSError: [Errno 22] Invalid argument

/mnt/c/Users/v-bowenz/OneDrive - Microsoft/Code/team-ai-virtual-try-on/code/backend/BackendManagement/models.py changed, reloading.
Performing system checks...

